Traceback (most recent call last):
  File "_unit_tests_utility.py", line 90, in <module>
    unit_tests.get_inputs()
  File "_unit_tests_utility.py", line 49, in get_inputs
    assert(input_line[0] in ('int', 'float', 'str'))
AssertionError
